<?xml version="1.0" ?>
<robot name="navrobot" xmlns:xacro="http://www.ros.org/wiki/xacro">

<xacro:include filename="$(find navrobot_description)/urdf/materials.xacro" />
<xacro:include filename="$(find navrobot_description)/urdf/navrobot.trans" />
<xacro:include filename="$(find navrobot_description)/urdf/navrobot.gazebo" />
<link name="base_link">
  <inertial>
    <origin rpy="0 0 0" xyz="0.0003147036812544579 8.654508451149124e-05 0.11079103947899595"/>
    <mass value="12.261671363008963"/>
    <inertia ixx="0.081478" ixy="-0.0" ixz="9.1e-05" iyy="0.132969" iyz="2.5e-05" izz="0.169987"/>
  </inertial>
  <visual>
    <origin rpy="0 0 0" xyz="0 0 0"/>
    <geometry>
      <mesh filename="package://navrobot_description/meshes/base_link.stl" scale="0.001 0.001 0.001"/>
    </geometry>
    <material name="silver"/>
  </visual>
  <collision>
    <origin rpy="0 0 0" xyz="0 0 0"/>
    <geometry>
      <mesh filename="package://navrobot_description/meshes/base_link.stl" scale="0.001 0.001 0.001"/>
    </geometry>
  </collision>
</link>

<link name="Component3_2">
  <inertial>
    <origin rpy="0 0 0" xyz="0.020039540828919386 0.0458031981819553 -0.10267664671429488"/>
    <mass value="0.8855619105503734"/>
    <inertia ixx="0.001219" ixy="-0.0" ixz="-0.0" iyy="0.00192" iyz="-0.0" izz="0.001219"/>
  </inertial>
  <visual>
    <origin rpy="0 0 0" xyz="-0.080388 -0.11879 -0.165353"/>
    <geometry>
      <mesh filename="package://navrobot_description/meshes/Component3_2.stl" scale="0.001 0.001 0.001"/>
    </geometry>
    <material name="silver"/>
  </visual>
  <collision>
    <origin rpy="0 0 0" xyz="-0.080388 -0.11879 -0.165353"/>
    <geometry>
      <mesh filename="package://navrobot_description/meshes/Component3_2.stl" scale="0.001 0.001 0.001"/>
    </geometry>
  </collision>
</link>

<link name="Component3_1">
  <inertial>
    <origin rpy="0 0 0" xyz="0.020039540828919386 0.045803198181955246 -0.10267664731034133"/>
    <mass value="0.8855619105503734"/>
    <inertia ixx="0.001219" ixy="-0.0" ixz="-0.0" iyy="0.00192" iyz="-0.0" izz="0.001219"/>
  </inertial>
  <visual>
    <origin rpy="0 0 0" xyz="0.119612 -0.11879 -0.165353"/>
    <geometry>
      <mesh filename="package://navrobot_description/meshes/Component3_1.stl" scale="0.001 0.001 0.001"/>
    </geometry>
    <material name="silver"/>
  </visual>
  <collision>
    <origin rpy="0 0 0" xyz="0.119612 -0.11879 -0.165353"/>
    <geometry>
      <mesh filename="package://navrobot_description/meshes/Component3_1.stl" scale="0.001 0.001 0.001"/>
    </geometry>
  </collision>
</link>

<link name="Component3_4">
  <inertial>
    <origin rpy="0 0 0" xyz="0.020039540270125847 0.01580319818195519 -0.10267664731034133"/>
    <mass value="0.8855619105503734"/>
    <inertia ixx="0.001219" ixy="-0.0" ixz="-0.0" iyy="0.00192" iyz="-0.0" izz="0.001219"/>
  </inertial>
  <visual>
    <origin rpy="0 0 0" xyz="0.119612 0.18121 -0.165353"/>
    <geometry>
      <mesh filename="package://navrobot_description/meshes/Component3_4.stl" scale="0.001 0.001 0.001"/>
    </geometry>
    <material name="silver"/>
  </visual>
  <collision>
    <origin rpy="0 0 0" xyz="0.119612 0.18121 -0.165353"/>
    <geometry>
      <mesh filename="package://navrobot_description/meshes/Component3_4.stl" scale="0.001 0.001 0.001"/>
    </geometry>
  </collision>
</link>

<link name="Component3_3">
  <inertial>
    <origin rpy="0 0 0" xyz="0.020039540828919247 0.01580319818195522 -0.10267664671429488"/>
    <mass value="0.8855619105503734"/>
    <inertia ixx="0.001219" ixy="-0.0" ixz="-0.0" iyy="0.00192" iyz="-0.0" izz="0.001219"/>
  </inertial>
  <visual>
    <origin rpy="0 0 0" xyz="-0.080388 0.18121 -0.165353"/>
    <geometry>
      <mesh filename="package://navrobot_description/meshes/Component3_3.stl" scale="0.001 0.001 0.001"/>
    </geometry>
    <material name="silver"/>
  </visual>
  <collision>
    <origin rpy="0 0 0" xyz="-0.080388 0.18121 -0.165353"/>
    <geometry>
      <mesh filename="package://navrobot_description/meshes/Component3_3.stl" scale="0.001 0.001 0.001"/>
    </geometry>
  </collision>
</link>

<joint name="Rev2" type="continuous">
  <origin rpy="0 0 0" xyz="0.080388 0.11879 0.165353"/>
  <parent link="base_link"/>
  <child link="Component3_2"/>
  <axis xyz="0.0 1.0 0.0"/>
</joint>

<joint name="Rev3" type="continuous">
  <origin rpy="0 0 0" xyz="-0.119612 0.11879 0.165353"/>
  <parent link="base_link"/>
  <child link="Component3_1"/>
  <axis xyz="0.0 1.0 0.0"/>
</joint>

<joint name="Rev4" type="continuous">
  <origin rpy="0 0 0" xyz="-0.119612 -0.18121 0.165353"/>
  <parent link="base_link"/>
  <child link="Component3_4"/>
  <axis xyz="-0.0 -1.0 -0.0"/>
</joint>

<joint name="Rev5" type="continuous">
  <origin rpy="0 0 0" xyz="0.080388 -0.18121 0.165353"/>
  <parent link="base_link"/>
  <child link="Component3_3"/>
  <axis xyz="-0.0 -1.0 -0.0"/>
</joint>

</robot>
